import React from 'react'
import { render, screen, fireEvent } from '@testing-library/react'
import { describe, it, expect, vi, beforeEach, afterEach } from 'vitest'
import { ErrorBoundary } from '@/components/ui/error-boundary'

// Mock component that throws an error
const ThrowError = ({ shouldThrow }: { shouldThrow: boolean }) => {
  if (shouldThrow) {
    throw new Error('Test error message')
  }
  return <div>No error</div>
}

// Mock console.error to avoid noise in tests
const originalConsoleError = console.error
beforeEach(() => {
  console.error = vi.fn()
})

afterEach(() => {
  console.error = originalConsoleError
})

describe('ErrorBoundary', () => {
  it('renders children when there is no error', () => {
    render(
      <ErrorBoundary>
        <ThrowError shouldThrow={false} />
      </ErrorBoundary>
    )

    expect(screen.getByText('No error')).toBeInTheDocument()
  })

  it('catches errors and displays default error UI', () => {
    render(
      <ErrorBoundary>
        <ThrowError shouldThrow={true} />
      </ErrorBoundary>
    )

    expect(screen.getByText('Something went wrong')).toBeInTheDocument()
    expect(screen.getByText('Test error message')).toBeInTheDocument()
    expect(screen.getByRole('button', { name: /try again/i })).toBeInTheDocument()
  })

  it('displays custom fallback UI when provided', () => {
    const customFallback = <div>Custom error message</div>

    render(
      <ErrorBoundary fallback={customFallback}>
        <ThrowError shouldThrow={true} />
      </ErrorBoundary>
    )

    expect(screen.getByText('Custom error message')).toBeInTheDocument()
    expect(screen.queryByText('Something went wrong')).not.toBeInTheDocument()
  })

  it('calls onError callback when error occurs', () => {
    const onError = vi.fn()

    render(
      <ErrorBoundary onError={onError}>
        <ThrowError shouldThrow={true} />
      </ErrorBoundary>
    )

    expect(onError).toHaveBeenCalledWith(
      expect.any(Error),
      expect.objectContaining({
        componentStack: expect.any(String)
      })
    )
  })

  it('resets error state when retry button is clicked', () => {
    const TestComponent = () => {
      const [shouldThrow, setShouldThrow] = React.useState(true)

      React.useEffect(() => {
        // After 100ms, stop throwing error to simulate fix
        const timer = setTimeout(() => setShouldThrow(false), 100)
        return () => clearTimeout(timer)
      }, [])

      return <ThrowError shouldThrow={shouldThrow} />
    }

    render(
      <ErrorBoundary>
        <TestComponent />
      </ErrorBoundary>
    )

    // Error should be displayed initially
    expect(screen.getByText('Something went wrong')).toBeInTheDocument()

    // Wait for the component to "fix" itself
    setTimeout(() => {
      // Click retry button
      fireEvent.click(screen.getByRole('button', { name: /try again/i }))

      // Should show the working component
      expect(screen.getByText('No error')).toBeInTheDocument()
      expect(screen.queryByText('Something went wrong')).not.toBeInTheDocument()
    }, 150)
  })

  it('logs errors to console for debugging', () => {
    const consoleSpy = vi.spyOn(console, 'error').mockImplementation(() => {})

    render(
      <ErrorBoundary>
        <ThrowError shouldThrow={true} />
      </ErrorBoundary>
    )

    expect(consoleSpy).toHaveBeenCalledWith(
      'ErrorBoundary caught an error:',
      expect.any(Error),
      expect.objectContaining({
        componentStack: expect.any(String)
      })
    )

    consoleSpy.mockRestore()
  })

  it('handles errors with no message gracefully', () => {
    const ThrowErrorWithoutMessage = () => {
      throw new Error()
    }

    render(
      <ErrorBoundary>
        <ThrowErrorWithoutMessage />
      </ErrorBoundary>
    )

    expect(screen.getByText('Something went wrong')).toBeInTheDocument()
    expect(screen.getByText('An unexpected error occurred while rendering this component.')).toBeInTheDocument()
  })
})